<?xml version="1.0" encoding="UTF-8"?>
<robot xmlns:xacro="http://www.ros.org/wiki/xacro" name="sugar_robot">
  <xacro:property name="PI" value="3.1415926535897931"/>

  <!-- import gazebo reference -->
  <xacro:include filename="$(find sugar_description)/urdf/sugar_robot.gazebo"/>

  <!-- import livox 3D-lidar model -->
  <xacro:include filename="$(find ros2_livox_simulation)/urdf/mid360.xacro"/>
  <xacro:mid360 name="livox" parent="lidar_stand" topic="mid360">
    <origin xyz="0.1 0 0.35" rpy="0 0 0"/>
  </xacro:mid360>
  
  <!-- base footprint -->
  <link name="base_footprint"/>

  <!-- base link -->
  <joint name="base_joint" type="fixed">
    <parent link="base_footprint"/>
    <child link="base_link"/>
    <origin xyz="0.0 0.0 0.1" rpy="0 0 0"/>
  </joint>
  <link name="base_link">
    <visual>
      <origin xyz="0.0 0.0 0.2" rpy="0 0 0"/>
      <geometry>
        <box size="0.9 0.5 0.4"/>
      </geometry>
      <material name="white">
        <color rgba="1.0 1.0 1.0 1.0"/>
      </material>
    </visual>
    <collision>
      <origin xyz="0.0 0.0 0.2" rpy="0 0 0"/>
      <geometry>
        <box size="0.9 0.5 0.4"/>
      </geometry>
    </collision>
    <inertial>
      <mass value="27.1"/>
      <origin xyz="-0.1995 0.0 0.19" rpy="0.0 0.0 0.0"/>
      <inertia ixx="0.78032248125" ixy="0.0" ixz="0.0" iyy="0.883913925" iyz="0.0" izz="1.25773640625"/>
    </inertial>
  </link>

  <!-- 3D-lidar stand -->
  <joint name="lidar_stand_joint" type="fixed">
    <parent link="base_link"/>
    <child link="lidar_stand"/>
    <origin xyz="-0.1 0.0 0.4" rpy="0 0 0"/>
  </joint>
  <link name="lidar_stand">
    <visual>
      <origin xyz="0.0 0.0 0.2" rpy="0 0 0"/>
      <geometry>
        <box size="0.1 0.05 0.4"/>
      </geometry>
      <material name="white">
        <color rgba="1.0 1.0 1.0 1.0"/>
      </material>
    </visual>
    <collision>
      <origin xyz="0.0 0.0 0.2" rpy="0 0 0"/>
      <geometry>
        <box size="0.1 0.05 0.4"/>
      </geometry>
    </collision>
  </link>

  <!-- livox 3D-lidar
  <joint name="lidar_joint" type="fixed">
    <parent link="lidar_stand"/>
    <child link="livox"/>
    <origin xyz="0.1 0.0 0.35" rpy="0 0 0"/>
  </joint>
  <link name="livox">
    <visual>
      <origin xyz="0.0 0.0 0.0" rpy="0 0 0"/>
      <geometry>
        <cylinder radius="0.05" length="0.05"/>
      </geometry>
      <material name="white">
        <color rgba="1.0 1.0 1.0 1.0"/>
      </material>
    </visual>
    <collision>
      <origin xyz="0.0 0.0 0.0" rpy="0 0 0"/>
      <geometry>
        <cylinder radius="0.05" length="0.05"/>
      </geometry>
    </collision>
  </link>-->

  <!-- left wheel -->
  <joint name="left_wheel_hinge" type="revolute">
    <parent link="base_link"/>
    <child link="left_wheel"/>
    <origin xyz="0.0 0.3 0.0" rpy="0.0 1.57079632679 1.57079632679"/>
    <axis xyz="0 0 1"/>
    <limit effort="100" velocity="100.0" lower="-5000" upper="5000"/>
  </joint>
  <link name="left_wheel">
    <visual>
      <origin xyz="0.0 0.0 0.0" rpy="0 0 0"/>
      <geometry>
        <cylinder radius="0.1015" length="0.047"/>
      </geometry>
      <material name="white">
        <color rgba="1.0 1.0 1.0 1.0"/>
      </material>
    </visual>
    <collision>
      <origin xyz="0.0 0.0 0.0" rpy="0 0 0"/>
      <geometry>
        <cylinder radius="0.1015" length="0.047"/>
      </geometry>
    </collision>
    <inertial>
      <mass value="3.4"/>
      <origin xyz="0.0 0.0 0.0" rpy="0.0 1.57079632679 1.57079632679"/>
      <inertia ixx="0.00938279583" ixy="0.0" ixz="0.0" iyy="0.00938279583" iyz="0.0" izz="0.017513825"/>
    </inertial>
  </link>

  <!-- right wheel -->
  <joint name="right_wheel_hinge" type="revolute">
    <parent link="base_link"/>
    <child link="right_wheel"/>
    <origin xyz="0.0 -0.3 0.0" rpy="0.0 1.57079632679 1.57079632679"/>
    <axis xyz="0 0 1"/>
    <limit effort="100" velocity="100.0" lower="-5000" upper="5000"/>
  </joint>
  <link name="right_wheel">
    <visual>
      <origin xyz="0.0 0.0 0.0" rpy="0 0 0"/>
      <geometry>
        <cylinder radius="0.1015" length="0.047"/>
      </geometry>
      <material name="white">
        <color rgba="1.0 1.0 1.0 1.0"/>
      </material>
    </visual>
    <collision>
      <origin xyz="0.0 0.0 0.0" rpy="0 0 0"/>
      <geometry>
        <cylinder radius="0.1015" length="0.047"/>
      </geometry>
    </collision>
    <inertial>
      <mass value="3.4"/>
      <origin xyz="0.0 0.0 0.0" rpy="0.0 1.57079632679 1.57079632679"/>
      <inertia ixx="0.00938279583" ixy="0.0" ixz="0.0" iyy="0.00938279583" iyz="0.0" izz="0.017513825"/>
    </inertial>
  </link>

  <!-- front left caster -->
  <joint name="front_left_caster_hinge" type="fixed">
    <parent link="base_link"/>
    <child link="front_left_caster"/>
    <origin xyz="0.2 0.15 -0.05" rpy="0.0 0.0 0.0"/>
  </joint>
  <link name="front_left_caster">
    <visual>
      <origin xyz="0.0 0.0 0.0" rpy="0.0 0.0 0.0"/>
      <geometry>
        <sphere radius="0.05"/>
      </geometry>
      <material name="white">
        <color rgba="1.0 1.0 1.0 1.0"/>
      </material>
    </visual>
    <collision>
      <origin xyz="0.0 0.0 0.0" rpy="0.0 0.0 0.0"/>
      <geometry>
        <sphere radius="0.05"/>
      </geometry>
    </collision>
  </link>

  <!-- front right caster -->
  <joint name="front_right_caster_hinge" type="fixed">
    <parent link="base_link"/>
    <child link="front_right_caster"/>
    <origin xyz="0.2 -0.15 -0.05" rpy="0.0 0.0 0.0"/>
  </joint>
  <link name="front_right_caster">
    <visual>
      <origin xyz="0.0 0.0 0.0" rpy="0.0 0.0 0.0"/>
      <geometry>
        <sphere radius="0.05"/>
      </geometry>
      <material name="white">
        <color rgba="1.0 1.0 1.0 1.0"/>
      </material>
    </visual>
    <collision>
      <origin xyz="0.0 0.0 0.0" rpy="0.0 0.0 0.0"/>
      <geometry>
        <sphere radius="0.05"/>
      </geometry>
    </collision>
  </link>

  <!-- rear left caster -->
  <joint name="rear_left_caster_hinge" type="fixed">
    <parent link="base_link"/>
    <child link="rear_left_caster"/>
    <origin xyz="-0.35 0.15 -0.05" rpy="0.0 0.0 0.0"/>
  </joint>
  <link name="rear_left_caster">
    <visual>
      <origin xyz="0.0 0.0 0.0" rpy="0.0 0.0 0.0"/>
      <geometry>
        <sphere radius="0.05"/>
      </geometry>
      <material name="white">
        <color rgba="1.0 1.0 1.0 1.0"/>
      </material>
    </visual>
    <collision>
      <origin xyz="0.0 0.0 0.0" rpy="0.0 0.0 0.0"/>
      <geometry>
        <sphere radius="0.05"/>
      </geometry>
    </collision>
  </link>

  <!-- rear right caster -->
  <joint name="rear_right_caster_hinge" type="fixed">
    <parent link="base_link"/>
    <child link="rear_right_caster"/>
    <origin xyz="-0.35 -0.15 -0.05" rpy="0.0 0.0 0.0"/>
  </joint>
  <link name="rear_right_caster">
    <visual>
      <origin xyz="0.0 0.0 0.0" rpy="0.0 0.0 0.0"/>
      <geometry>
        <sphere radius="0.05"/>
      </geometry>
      <material name="white">
        <color rgba="1.0 1.0 1.0 1.0"/>
      </material>
    </visual>
    <collision>
      <origin xyz="0.0 0.0 0.0" rpy="0.0 0.0 0.0"/>
      <geometry>
        <sphere radius="0.05"/>
      </geometry>
    </collision>
  </link>
</robot>

